[Table of Contents](/README.md) | [Previous Section (Go to Previous Chapter)](../../Module%208/Pearson%20Notes/15.8%20-%20Multiple%20Inheritance.md) | [Next Section](16.2%20-%20Function%20Templates.md) | [All Sections](/Module%209/Pearson%20Notes/)
***
#Module9 #PearsonNotes <br />

### Since this is a long section here are a table of contents for each section (In Order):
#### Table of Contents
- 16.1 - Exceptions
- [Object-Oriented Exception Handling with Classes](#Object-Oriented-Exception-Handling-with-Classes)
- [Multiple Exceptions](#Multiple-Exceptions)
- [Extracting Data from the Exception Class](#Extracting-Data-from-the-Exception-Class)
- [Unwinding the Stack](#Unwinding-the-Stack)
- [Rethrowing an Exception](#Rethrowing-an-Exception)
- [Handling the `bad_alloc` Exception](#Handling-the-bad_alloc-Exception)
- [Using the `noexcept` Key Word](#Using-the-noexcept-Key-Word)
***
# 16.1 - Exceptions
One way of handling complex error conditions is with **exceptions**. An exception is a value or an object that signals an error. When the error occurs, an exception is “thrown.” For example, the following code shows the `divide` function, modified to throw an exception when division by zero has been attempted:
```c++
double divide(int numerator, int denominator)
{
  if (denominator == 0)
    throw "ERROR: Cannot divide by zero.\n";
  else
    return static_cast<double>(numerator) / denominator;
}
```

The following statement causes the exception to be thrown:
```c++
throw "ERROR: Cannot divide by zero.\n";
```
The `throw` key word is followed by an argument, which can be any value. As you will see, the value of the argument will be used to determine the nature of the error. The function above simply throws a string containing an error message.

The line containing a throw statement is known as the **throw point**. When a `throw` statement is executed, the function that has thrown the exception aborts its execution and control is passed to another part of the program known as an **exception handler**. The exception handler gracefully responds to the error condition, rather than letting the program abruptly terminate.

To handle an exception, a program must have a *try/catch* construct. The general format of the try/catch construct is:
```c++
try {
  // code here calls functions or object member
  // functions that might throw an exception.
} catch (ExceptionParameter) {
  // code here handles the exception
}
// Repeat as many catch blocks as needed.
```
The first part of the construct is the **try block**. This starts with the key word `try` and is followed by a block of code executing any statements that might directly or indirectly cause an exception to be thrown. The try block is immediately followed by one or more **catch blocks**, which are the exception handlers. A `catch` block starts with the key word catch, followed by a set of parentheses containing the definition of an exception parameter. For example, here is a try/catch construct that can be used with the `divide` function:
```C++
try {
  quotient = divide(num1, num2);
  cout << "The quotient is " << quotient << endl;
} catch (string exceptionString) {
  cout << exceptionString;
}
```

Because the `divide` function throws an exception whose value is a string, there must be an exception handler that catches a string. The catch block shown catches the error message in the `exceptionString` parameter then displays it with `cout`. Now let’s look at an entire program to see how throw, `try`, and `catch` work together. 

### Program 16-1
In the first sample run of this program, valid data are given. This shows how the program should run with no errors. In the second sample running, a denominator of 0 is given. This shows the result of the exception being thrown.
```c++
 // This program demonstrates an exception being thrown and caught.
 #include <iostream>
 #include <string>
 using namespace std;

 // Function prototype
 double divide(int, int);

 int main()
 {
     int num1, num2; // To hold two numbers
     double quotient; // To hold the quotient of the numbers

     // Get two numbers.
     cout << "Enter two numbers: ";
     cin >> num1 >> num2;
     
     // Divide num1 by num2 and catch any
     // potential exceptions.
     try
     {
          quotient = divide(num1, num2);
          cout << "The quotient is " << quotient << endl;
     }
     catch (string exceptionString)
     {
          cout << exceptionString;
     }

     cout << "End of the program.\n";
     return 0;
 }
 
 //*********************************************
 // The divide function divides the numerator  *
 // by the denominator. If the denominator is  *
 // zero, the function throws an exception.    *
 //*********************************************

 double divide(int numerator, int denominator)
 {
     if (denominator == 0)
     {
         string exceptionString = "ERROR: Cannot divide by zero.\n";
         throw exceptionString;
     }

     return static_cast<double>(numerator) / denominator;
 }
// ============== Example Output 1 ==============
// Enter two numbers: 12 2 [Enter]
// The quotient is 6
// End of the program.
// ==============================================

// ============== Example Output 2 ==============
// Enter two numbers: 12 0 [Enter]
// ERROR: Cannot divide by zero.
// End of the program.
// ==============================================
```
As you can see from the second output screen, the exception caused the program to jump out of the `divide` function and into the catch block. After the catch block has finished, the program resumes with the first statement after the try/catch construct. This is illustrated in [Figure 16-1](#Figure-16-1).

### Figure 16-1
How the try/catch construct works <br />
![Figure 16-1](16.1%20Photos/16.1%20-%20Figure%2016-1.png) <br />

In the first output screen, the user entered nonnegative values. No exception was thrown in the try block, so the program skipped the catch block and jumped to the statement immediately following the try/catch construct, which is in line 30. This is illustrated in [Figure 16-2](#Figure-16-2).

### Figure 16-2
No exception was thrown <br />
![Figure 16-2](16.1%20Photos/16.1%20-%20Figure%2016-2.png) <br />

## What if an Exception is Not Caught?
There are two possible ways for a thrown exception to go uncaught. The first possibility is for the try/catch construct to contain no catch blocks with an exception parameter of the right data type. The second possibility is for the exception to be thrown from outside a try block. In either case, the exception will cause the entire program to abort execution.

#### [Back To The Top](#Table-of-Contents)

# Object-Oriented Exception Handling with Classes
Now that you have an idea of how the exception mechanism in C++ works, we will examine an object-oriented approach to exception handling. Recall the [Rectangle class that was introduced in Chapter 13](../../Module%206/Pearson%20Notes/13.2%20-%20Introduction%20to%20Classes.md#Rectangle-Class-Example). That class had the `mutator` functions `setWidth` and `setLength` for setting the rectangle’s width and length. If a negative value was passed to either of these functions, the class displayed an error message and aborted the program. The following code shows an improved version of the Rectangle class. This version throws an exception when a negative value is passed to `setWidth` or `setLength`. 

#### Contents of `Rectangle.h` (v1)
```c++
 // Specification file for the Rectangle class
 #ifndef RECTANGLE_H
 #define RECTANGLE_H

 class Rectangle
 {
     private:
         double width;    // The rectangle's width
         double length;   // The rectangle's length
     public:
         // Exception class
         class NegativeSize
             { };         // Empty class declaration

         // Default constructor
         Rectangle()
             { width = 0.0; length = 0.0; }

         // Mutator functions, defined in Rectangle.cpp
         void setWidth(double);
         void setLength(double);

         // Accessor functions
         double getWidth() const
             { return width; }

         double getLength() const
             { return length; }

         double getArea() const
             { return width * length; }
 };
 #endif
```
Notice the empty class declaration that appears in the public section, in lines 12 and 13. The `NegativeSize` class has no members. The only important part of the class is its name, which will be used in the exception-handling code. Now look at the `Rectangle.cpp `file, where the `setWidth` and `setLength` member functions are defined.

#### Contents of `Rectangle.cpp` (v1)
```c++
 // Implementation file for the Rectangle class.
 #include "Rectangle.h"

 //*********************************************************
 // setWidth sets the value of the member variable width.  *
 //*********************************************************

 void Rectangle::setWidth(double w)
 {
     if (w >= 0)
         width = w;
     else
         throw NegativeSize();
 }
 
 //***********************************************************
 // setLength sets the value of the member variable length.  *
 //***********************************************************

 void Rectangle::setLength(double len)
 {
    if (len >= 0)
        length = len;
    else
        throw NegativeSize();
 }
```
In the `setWidth` function, the parameter `w` is tested by the `if` statement in line 10. If `w` is greater than or equal to 0, its value is assigned to the `width` member variable. If w holds a negative number, however, the statement in line 13 is executed.
```c++
throw NegativeSize();
```

The `throw` statement’s argument, `NegativeSize()`, causes an instance of the `NegativeSize` class to be created and thrown as an exception.

The same series of events takes place in the `setLength` function. If the value in the `len` parameter is greater than or equal to 0, its value is assigned to the length member variable. If `len` holds a negative number, an instance of the `NegativeSize` class is thrown as an exception in line 25.

This way of reporting errors is much more graceful than simply aborting the program. Any code that uses the `Rectangle` class must simply have a catch block to handle the `NegativeSize` exceptions that the `Rectangle` class might throw.

## Program 16-2
```c++
 // This program demonstrates Rectangle class exceptions.
 #include <iostream>
 #include "Rectangle.h"
 using namespace std;

 int main()
 {
    double width;
    double length;

    // Get the width and length.
    Rectangle myRectangle;

    // Get the width and length.
    cout << "Enter the rectangle's width: ";
    cin >> width;
    cout << "Enter the rectangle's length: ";
    cin >> length;


    // Store these values in the Rectangle object.
    try
    {
       myRectangle.setWidth(width);
       myRectangle.setLength(length);
       cout << "The area of the rectangle is "
            << myRectangle.getArea() << endl;
    }
    catch (Rectangle::NegativeSize)
    {
       cout << "Error: A negative value was entered.\n";
    }
    cout << "End of the program.\n";

    return 0;
}

// ============== Example Output 1 ===============
// Enter the rectangle's width: 10 [Enter]
// Enter the rectangle's length: 20 [Enter]
// The area of the rectangle is 200
// End of the program.
// ===============================================

// ============== Example Output 2 ===============
// Enter the rectangle's width: 5 [Enter]
// Enter the rectangle's length: −5 [Enter]
// Error: A negative value was entered.
// End of the program.
// ===============================================
```
The `catch` statement in line 28 catches the `NegativeSize` exception when it is thrown by any of the statements in the try block. Inside the `catch` statement’s parentheses is the name of the `NegativeSize` class. Because the `NegativeSize` class is declared inside the `Rectangle` class, we have to fully qualify the class name with the scope resolution operator.

Notice we did not define a parameter of the `NegativeSize` class in the `catch` statement. In this case, the `catch` statement only needs to specify the type of exception it handles.

#### [Back To The Top](#Table-of-Contents)

# Multiple Exceptions
The programs we have studied so far test only for a single type of error and throw only a single type of exception. In many cases, a program will need to test for several different types of errors and signal which one has occurred. C++ allows you to throw and catch multiple exceptions. The only requirement is that each different exception be of a different type. You then code a separate catch block for each type of exception that may be thrown in the try block.

For example, suppose we wish to expand the `Rectangle` class so it throws one type of exception when a negative value is specified for the `width`, and another type of exception when a negative value is specified for the `length`. First, we declare two different exception classes, such as:
```c++
// Exception class for a negative width
class NegativeWidth { };

// Exception class for a negative length
class NegativeLength { };
```

An instance of `NegativeWidth` will be thrown when a negative value is specified for the `width`, and an instance of `NegativeLength` will be thrown when a negative value is specified for the `length`. The code for the modified `Rectangle` class is shown here.

#### Contents of `Rectangle.h` (v2)
```c++
 // Specification file for the Rectangle class
 #ifndef RECTANGLE_H
 #define RECTANGLE_H

 class Rectangle
 {
     private:
         double width;      // The rectangle's width
         double length;     // The rectangle's length
     public:
         // Exception class for a negative width
         class NegativeWidth
             { };

         // Exception class for a negative length
         class NegativeLength
             { };

         // Default constructor
         Rectangle()
             { width = 0.0; length = 0.0; }

         // Mutator functions, defined in Rectangle.cpp
         void setWidth(double);
         void setLength(double);

         // Accessor functions
         double getWidth() const
              { return width; }
              
         double getLength() const
              { return length; }

         double getArea() const
              { return width * length; }
 };
 #endif
```

#### Contents of `Rectangle.cpp` (v2)
```c++
 // Implementation file for the Rectangle class.
 #include "Rectangle.h"

 //***********************************************************
 // setWidth sets the value of the member variable width.    *
 //***********************************************************

 void Rectangle::setWidth(double w)
 {
    if (w >= 0)
       width = w;
    else
       throw NegativeWidth();
 }

 //***********************************************************
 // setLength sets the value of the member variable length.  *
 //***********************************************************

 void Rectangle::setLength(double len)
 {
    if (len >= 0)
       length = len;
    else
       throw NegativeLength();
 }
```
Notice in the definition of the `setWidth` function (in `Rectangle.cpp`) that an instance of the `NegativeWidth` class is thrown in line 13. In the definition of the `setLength` function, an instance of the `NegativeLength` class is thrown in line 25. 

### Program 16-3
```c++
 // This program demonstrates Rectangle class exceptions.
 #include <iostream>
 #include "Rectangle.h"
 using namespace std;

 int main()
 {
     double width;
     double length;

     // Create a Rectangle object.
     Rectangle myRectangle;

     // Get the width and length.
     cout << "Enter the rectangle's width: ";
     cin >> width;
     cout << "Enter the rectangle's length: ";
     cin >> length;

     // Store these values in the Rectangle object.
     try
     {
        myRectangle.setWidth(width);
        myRectangle.setLength(length);
        cout << "The area of the rectangle is "
             << myRectangle.getArea() << endl;
      }
      catch (Rectangle::NegativeWidth)
      {
         cout << "Error: A negative value was given "
              << "for the rectangle's width.\n";
      }
      catch (Rectangle::NegativeLength)
      {
         cout << "Error: A negative value was given "

              << "for the rectangle's length.\n";
      }

      cout << "End of the program.\n";
      return 0;
  }

// ============== Example Output 1 ===============
// Enter the rectangle's width: 10 [Enter]
// Enter the rectangle's width: 20 [Enter]
// The area of the rectangle is 200
// End of the program.
// ===============================================


// ============== Example Output 2 ===============
// Enter the rectangle's width: −5 [Enter]
// Enter the rectangle's length: 5 [Enter]
// Error: A negative value was given for the rectangle's width.
// End of the program.
// ===============================================


// ============== Example Output 3 ===============
// Enter the rectangle's width: 5 [Enter]
// Enter the rectangle's length: −5 [Enter]
// Error: A negative value was given for the rectangle's length.
// End of the program.
// ===============================================
```
The try block, in lines 21 through 27, contains code that can throw two different types of exceptions. The statement in line 23 can potentially throw a `NegativeWidth` exception, and the statement in line 24 can potentially throw a `NegativeLength` exception. To handle each of these types of exception, there are two catch statements. The statement in line 28 catches `NegativeWidth` exceptions, and the statement in line 33 catches `NegativeLength` exceptions.

When an exception is thrown by code in the try block, C++ searches the try/catch construct for a `catch` statement that can handle the exception. If the construct contains a `catch` statement that is compatible with the exception, control of the program is passed to the catch block.

## Using Exception Handlers to Recover from Errors
[Program 16-3](#Program-16-3) demonstrates how a try/catch construct can have several catch statements in order to handle different types of exceptions. However, the program does not use the exception handlers to recover from any of the errors. When the user enters a negative value for either the width or the length, this program still halts. [Program 16-4](#Program-16-4) shows a better example of effective exception handling. It attempts to recover from the exceptions and get valid data from the user. 

### Program 16-4
```c++
 // This program handles the Rectangle class exceptions.
 #include <iostream>
 #include "Rectangle.h"
 using namespace std;

 int main()
 {
     double width;           // Rectangle's width
     double length;          // Rectangle's length
     bool tryAgain = true;   // Flag to reread input

     // Create a Rectangle object.
     Rectangle myRectangle;

     // Get the rectangle's width.
     cout << "Enter the rectangle's width: ";
     cin >> width;

     // Store the width in the myRectangle object.
     while (tryAgain)
     {
         try
         {
             myRectangle.setWidth(width);
             // If no exception was thrown, then the
             // next statement will execute.
             tryAgain = false;
         }
         catch (Rectangle::NegativeWidth)
         {
             cout << "Please enter a nonnegative value: ";
             cin >> width;
         }
     }
     
     // Get the rectangle's length.
     cout << "Enter the rectangle's length: ";
     cin >> length;

     // Store the length in the myRectangle object
     tryAgain = true;
     while (tryAgain)
     {
          try
          {
              myRectangle.setLength(length);
              
              // If no exception was thrown, then the
              // next statement will execute.
              tryAgain = false;
          }
          catch (Rectangle::NegativeLength)
          {
              cout << "Please enter a nonnegative value: ";
              cin >> length;
          }
     }

     // Display the area of the rectangle.
     cout << "The rectangle's area is "
          << myRectangle.getArea() << endl;
     return 0;
}

// =================== Output ===================
// Enter the rectangle's width: −1 [Enter]
// Please enter a nonnegative value: 10 [Enter]
// Enter the rectangle's length: −5 [Enter]
// Please enter a nonnegative value: 50 [Enter]
// The rectangle's area is 500
// ===============================================
```
Let’s look at how this program recovers from a `NegativeWidth` exception. In line 10, a bool flag variable, `tryAgain`, is defined and initialized with the value `true`. This variable will indicate whether we need to get a value from the user again. Lines 16 and 17 prompt the user to enter the rectangle’s width. Then, the program enters the `while` loop in lines 20 through 34. The loop repeats as long as `tryAgain` is true. Inside the loop, the `Rectangle` class’s `setWidth` member function is called in line 24. This statement is in a try block. If a `NegativeWidth` exception is thrown, the program will jump to the `catch` statement in line 29. In the catch block that follows, the user is asked to enter a nonnegative number. The program then jumps out of the try/catch construct. Because `tryAgain` is still `true`, the loop will repeat.

If a nonnegative number is passed to the `setWidth` member function in line 24, no exception will be thrown. In that case, the statement in line 27 will execute, which sets `tryAgain` to `false`. The program then jumps out of the try/catch construct. Because `tryAgain` is now `false`, the loop will not repeat.

The same strategy is used in lines 37 through 56 to get and validate the rectangle’s length.

#### [Back To The Top](#Table-of-Contents)

# Extracting Data from the Exception Class
Sometimes we might want an exception object to pass data back to the exception handler. For example, suppose we would like the `Rectangle` class not only to signal when a negative value has been given, but also to pass the value back. This can be accomplished by giving the exception class members in which data can be stored.

In our next modification of the Rectangle class, the `NegativeWidth` and `NegativeLength` classes have been expanded, each with a member variable and a constructor. Here is the code for the `NegativeWidth` class:
```c++
class NegativeWidth {
  private:
  double value;

  public:
  NegativeWidth(double val) { value = val; }

  double getValue() const { return value; }
};
```

When we throw this exception, we want to pass the invalid value as an argument to the class’s constructor. This is done in the `setWidth` member function with the following statement:
```c++
throw NegativeWidth(w);
```

This throw statement creates an instance of the `NegativeWidth` class and passes a copy of the w variable to the constructor. The constructor then stores this number in `NegativeWidth`’s member variable, `value`. The class instance carries this member variable to the catch block that intercepts the exception.

In the catch block, the value is extracted with code such as
```c++
catch (Rectangle::NegativeWidth e)
{
  cout << "Error: " << e.getValue()
	   << " is an invalid value for the"
       << " rectangle's width.\n";
}
```

Notice the catch block defines a parameter object named `e`﻿. This is necessary because we want to call the class’s `getValue` function to retrieve the value that caused the exception.

Here is the code for the `NegativeLength` class:
```c++
class NegativeLength {
  private:
  double value;

  public:
  NegativeLength(double val) { value = val; }

  double getValue() const { return value; }
};
```

This class also has a member variable named `value`, and a constructor that initializes the variable. When we throw this exception, we follow the same general steps that were just described for the `NegativeWidth` exception. The complete code for the revised `Rectangle` class is shown here.

#### Contents of `Rectangle.h` (v3)
```c++
 // Specification file for the Rectangle class
 #ifndef RECTANGLE_H
 #define RECTANGLE_H
 
 class Rectangle
 {
     private:
         double width;     // The rectangle's width
         double length;    // The rectangle's length
     public:
         // Exception class for a negative width
         class NegativeWidth
         {
         private:
             double value;
         public:
             NegativeWidth(double val)
                 { value = val; }

             double getValue() const
                 { return value; }
         };

         // Exception class for a negative length
         class NegativeLength
         {
         private:
             double value;
         public:
             NegativeLength(double val)
                 { value = val; }

             double getValue() const
                 { return value; }
         };

         // Default constructor
         Rectangle()
            { width = 0.0; length = 0.0; }

         // Mutator functions, defined in Rectangle.cpp
         void setWidth(double);
         void setLength(double);

         // Accessor functions
         double getWidth() const
             { return width; }

         double getLength() const
             { return length; }

         double getArea() const
             { return width * length; }
 };
 #endif
```

#### Contents of `Rectangle.cpp` (v3)
```c++
 // Implementation file for the Rectangle class.
 #include "Rectangle.h"

 //***********************************************************
 // setWidth sets the value of the member variable width.    *
 //***********************************************************

 void Rectangle::setWidth(double w)
 {
    if (w >= 0)
        width = w;
    else
        throw NegativeWidth(w);
 }

 //***********************************************************
 // setLength sets the value of the member variable length.  *
 //***********************************************************

 void Rectangle::setLength(double len)
 {
    if (len >= 0)
       length = len;
    else
       throw NegativeLength(len);
 }
```

## Program 16-5
```c++
 // This program demonstrates Rectangle class exceptions.
 #include <iostream>
 #include "Rectangle.h"
 using namespace std;

 int main()
 {
     double width;
     double length;

     // Create a Rectangle object.
     Rectangle myRectangle;

     // Get the width and length.
     cout << "Enter the rectangle's width: ";
     cin >> width;
     cout << "Enter the rectangle's length: ";
     cin >> length;
     
     // Store these values in the Rectangle object.
     try
     {
         myRectangle.setWidth(width);
         myRectangle.setLength(length);
         cout << "The area of the rectangle is "
              << myRectangle.getArea() << endl;
     }
     catch (Rectangle::NegativeWidth e)
     {
         cout << "Error: " << e.getValue()
              << " is an invalid value for the"
              << " rectangle's width.\n";
     }
     catch (Rectangle::NegativeLength e)
     {
         cout << "Error: " << e.getValue()
              << " is an invalid value for the"
              << " rectangle's length.\n";
      }

      cout << "End of the program.\n";
      return 0;
 }
 
// =============== Example Output 1 ===============
// Enter the rectangle's width: −1 [Enter]
// Enter the rectangle's length: 10 [Enter]
// Error: −1 is an invalid value for the rectangle's width.
// End of the program.
// ================================================

// =============== Example Output 2 ===============
// Enter the rectangle's width: 5 [Enter]
// Enter the rectangle's length: −1 [Enter]
// Error: −1 is an invalid value for the rectangle's length.
// End of the program.
// ================================================
```

#### [Back To The Top](#Table-of-Contents)

# Unwinding the Stack
Once an exception has been thrown, the program cannot jump back to the throw point. The function that executes a `throw` statement will immediately terminate. If that function was called by another function, and the exception is not caught, then the calling function will terminate as well. This process, known as **unwinding the stack**, continues for the entire chain of nested function calls, from the throw point, all the way back to the try block.
#### [Back To The Top](#Table-of-Contents)

# Rethrowing an Exception
It is possible for try blocks to be nested. For example, look at this code segment:
```c++
try {
  doSomething();
} catch (exception1) {
  // code to handle exception 1
} catch (exception2) {
  // code to handle exception 2
}
```
In this try block, the function `doSomething` is called. There are two catch blocks, one that handles `exception1`, and another that handles `exception2`. If the `doSomething` function also has a try block, then it is nested inside the one shown.

With nested try blocks, it is sometimes necessary for an inner exception handler to pass an exception to an outer exception handler. Sometimes both an inner and an outer catch block must perform operations when a particular exception is thrown. These situations require that the inner catch block **rethrow** the exception so the outer catch block has a chance to catch it.

A catch block can rethrow an exception with the throw statement. For example, suppose the `doSomething` function (called in the throw block above) calls the `doSomethingElse` function, which potentially can throw `exception1` or `exception3`. Suppose `doSomething` does not want to handle `exception1`. Instead, it wants to rethrow it to the outer block. The following code segment illustrates how this is done:
```c++
try {
  doSomethingElse();
} catch (exception1) {
  throw; // Rethrow the exception
} catch (exception3) {
  // Code to handle exception 3
}
```
When the first catch block catches `exception1`, the `throw` statement simply throws the exception again. The catch block in the outer try/catch construct will then handle the exception.

#### [Back To The Top](#Table-of-Contents)

# Handling the `bad_alloc` Exception
Recall from [Chapter 9](/Module%202/Pearson%20Notes) that when the new operator fails to allocate memory, an exception is thrown. Now that you’ve seen how to handle exceptions, you can write code that determines whether the `new` operator was successful.

When the `new` operator fails to allocate memory, C++ throws a **`bad_alloc` exception**. The `bad_alloc` exception type is defined in the `<new>` header file, so any program that attempts to catch this exception should have the following directive:
```c++
#include <new>
```
The `bad_alloc` exception is in the std` `namespace, so be sure to have the `using namespace std;` statement in your code as well.

Here is the general format of a try/catch construct that catches the `bad_alloc` exception:
```c++
try {
  // Code that uses the new operator
} catch (bad_alloc) {
  // Code that responds to the error
}
```

## Program 16-6
The program uses the new operator to allocate a 10,000- element array of doubles. If the new operator fails, an error message is displayed.
```c++
 // This program demonstrates the bad_alloc exception.
 #include <iostream>
 #include <new>         // Needed for bad_alloc
 using namespace std;

 int main()
 {
     double *ptr = nullptr; // Pointer to double

     try
     {
         ptr = new double [10000];
     }
     catch (bad_alloc)
     {
         cout << "Insufficient memory.\n";
     }

     return 0;
 }
```

#### [Back To The Top](#Table-of-Contents)

# Using the `noexcept` Key Word
Beginning with C++ 11, you can declare a function with the `noexcept` specifier to indicate that the function does not throw an exception and does not call any other functions that throw an exception. Here is an example:
```c++
void sayHello() noexcept
{ cout << "Hello world" << endl; }
```

The primary purpose of the `noexcept` key word is to help the compiler produce faster code. We won’t discuss the details here, but when the compiler knows that a function cannot cause an uncaught exception to be thrown, it can optimize the executable code that it generates.

The `noexcept` key word is not meant to guarantee that no exceptions will be thrown, however. For example, in the following code, `myFunction` is declared as `noexcept`. It calls `anotherFunction`, which may or may not throw an exception. When you declare a function as `noexcept`, the compiler does not trace through the code to make sure that no exceptions are possible. If an exception is thrown from within a function that is declared as `noexcept`, the program’s execution will be terminated.
```c++
void myFunction() noexcept
{ anotherFunction(); }
```

You can also use the `noexcept` key word to specify that a function does not throw an exception under specific conditions. Here is the general format:
```c++
noexcept(BooleanExpression)
```

This general format specifies that the function does not throw an exception when the *`BooleanExpression`* is true. Here is an example:
```c++
double divide(int numerator, int denominator) noexcept(denominator != 0)
{ return static_cast<double>(numerator) / denominator; }
```
This code defines a function named `divide` that has two `int` parameters: numerator and denominator. The `noexcept` clause specifies that the function will not throw an exception when `denominator` is not equal to 0.

#### [Back To The Top](#Table-of-Contents)

***
[Table of Contents](/README.md) | [Previous Section (Go to Previous Chapter)](../../Module%208/Pearson%20Notes/15.8%20-%20Multiple%20Inheritance.md) | [Next Section](16.2%20-%20Function%20Templates.md) | [All Sections](/Module%209/Pearson%20Notes/)